<mujoco model="follower">
  <default>
    <default class="robot">
      <default class="motor">
        <joint />
        <motor />
      </default>
      <default class="visual">
        <geom material="visualgeom" contype="0" conaffinity="0" group="2" />
      </default>
      <default class="collision">
        <geom material="collision_material" condim="3" contype="0" conaffinity="1" priority="1" group="1" solref="0.005 1" friction="1 0.01 0.01" />
        <equality solimp="0.99 0.999 1e-05" solref="0.005 1" />
      </default>
    </default>
  </default>

  <compiler angle="radian" />

  <asset>
    <material name="mat1" rgba="0.79216 0.81961 0.93333 1" />
    <material name="default_material" rgba="0.7 0.7 0.7 1" />
    <material name="collision_material" rgba="1.0 0.28 0.1 0.9" />
    <mesh name="base_link.STL" file="meshes/base_link.STL" />
    <mesh name="base_link_motor.STL" file="meshes/base_link_motor.STL" />
    <mesh name="link_1.STL" file="meshes/link_1.STL" />
    <mesh name="link_1_motor.STL" file="meshes/link_1_motor.STL" />
    <mesh name="link_2.STL" file="meshes/link_2.STL" />
    <mesh name="link_2_motor.STL" file="meshes/link_2_motor.STL" />
    <mesh name="link_3.STL" file="meshes/link_3.STL" />
    <mesh name="link_3_motor.STL" file="meshes/link_3_motor.STL" />
    <mesh name="link_4.STL" file="meshes/link_4.STL" />
    <mesh name="link_4_motor.STL" file="meshes/link_4_motor.STL" />
    <mesh name="link_5.STL" file="meshes/link_5.STL" />
    <mesh name="link_5_motor.STL" file="meshes/link_5_motor.STL" />
    <mesh name="link_6.STL" file="meshes/link_6.STL" />
  </asset>

  <worldbody>
    <body name="base_link" pos="0.00000000 0.00000000 0.00000000" quat="1 0 0 0" childclass="robot">
      <freejoint name="floating_base" />
      <geom name="base_link_collision_0" pos="0 0 0" quat="1.0 0.0 0.0 0.0" type="mesh" mesh="base_link.STL" class="collision" />
      <geom name="base_link_collision_1" pos="0 0 0" quat="1.0 0.0 0.0 0.0" type="mesh" mesh="base_link_motor.STL" class="collision" />
      <geom name="base_link_visual_0" pos="0 0 0" quat="1.0 0.0 0.0 0.0" material="" type="mesh" mesh="base_link.STL" class="visual" />
      <geom name="base_link_visual_1" pos="0 0 0" quat="1.0 0.0 0.0 0.0" material="" type="mesh" mesh="base_link_motor.STL" class="visual" />
      <body name="link_1" pos="0.012 0 0.0409" quat="1.0 0.0 0.0 0.0">
        <joint name="joint_1" type="hinge" ref="0.0" class="motor" range="-3.14 3.14" axis="0 0 -1" />
        <inertial pos="0.011924 -0.00048792 0.013381" quat="1.0 0.0 0.0 0.0" mass="0.05014" diaginertia="7.6045e-06 1.2358e-05 1.4492e-05" />
        <geom name="link_1_collision_0" pos="0 0 0" quat="1.0 0.0 0.0 0.0" type="mesh" mesh="link_1.STL" class="collision" />
        <geom name="link_1_collision_1" pos="0 0 0" quat="1.0 0.0 0.0 0.0" type="mesh" mesh="link_1_motor.STL" class="collision" />
        <geom name="link_1_visual_0" pos="0 0 0" quat="1.0 0.0 0.0 0.0" material="" type="mesh" mesh="link_1.STL" class="visual" />
        <geom name="link_1_visual_1" pos="0 0 0" quat="1.0 0.0 0.0 0.0" material="" type="mesh" mesh="link_1_motor.STL" class="visual" />
        <body name="link_2" pos="0 -0.0209 0.0154" quat="1.0 0.0 0.0 0.0">
          <joint name="joint_2" type="hinge" ref="0.0" class="motor" range="-3.14 3.14" axis="0 1 0" />
          <inertial pos="0.0011747 0.02097 0.071547" quat="1.0 0.0 0.0 0.0" mass="0.050177" diaginertia="3.7018e-05 3.3772e-05 8.2375e-06" />
          <geom name="link_2_collision_0" pos="0 0 0" quat="1.0 0.0 0.0 0.0" type="mesh" mesh="link_2.STL" class="collision" />
          <geom name="link_2_collision_1" pos="0 0 0" quat="1.0 0.0 0.0 0.0" type="mesh" mesh="link_2_motor.STL" class="collision" />
          <geom name="link_2_visual_0" pos="0 0 0" quat="1.0 0.0 0.0 0.0" material="" type="mesh" mesh="link_2.STL" class="visual" />
          <geom name="link_2_visual_1" pos="0 0 0" quat="1.0 0.0 0.0 0.0" material="" type="mesh" mesh="link_2_motor.STL" class="visual" />
          <body name="link_3" pos="-0.0148 0.0065 0.1083" quat="1.0 0.0 0.0 0.0">
            <joint name="joint_3" type="hinge" ref="0.0" class="motor" range="-3.14 3.14" axis="0 1 0" />
            <inertial pos="-0.05537 0.014505 0.0028659" quat="1.0 0.0 0.0 0.0" mass="0.06379" diaginertia="7.3427e-06 2.2231e-05 2.4506e-05" />
            <geom name="link_3_collision_0" pos="0 0 0" quat="1.0 0.0 0.0 0.0" type="mesh" mesh="link_3.STL" class="collision" />
            <geom name="link_3_collision_1" pos="0 0 0" quat="1.0 0.0 0.0 0.0" type="mesh" mesh="link_3_motor.STL" class="collision" />
            <geom name="link_3_visual_0" pos="0 0 0" quat="1.0 0.0 0.0 0.0" material="" type="mesh" mesh="link_3.STL" class="visual" />
            <geom name="link_3_visual_1" pos="0 0 0" quat="1.0 0.0 0.0 0.0" material="" type="mesh" mesh="link_3_motor.STL" class="visual" />
            <body name="link_4" pos="-0.10048 5E-05 0.0026999" quat="1.0 0.0 0.0 0.0">
              <joint name="joint_4" type="hinge" ref="0.0" class="motor" range="-3.14 3.14" axis="0 1 0" />
              <inertial pos="-0.02652 0.019195 -9.0614E-06" quat="1.0 0.0 0.0 0.0" mass="0.019805" diaginertia="2.9577e-06 1.0783e-06 2.8759e-06" />
              <geom name="link_4_collision_0" pos="0 0 0" quat="1.0 0.0 0.0 0.0" type="mesh" mesh="link_4.STL" class="collision" />
              <geom name="link_4_collision_1" pos="0 0 0" quat="1.0 0.0 0.0 0.0" type="mesh" mesh="link_4_motor.STL" class="collision" />
              <geom name="link_4_visual_0" pos="0 0 0" quat="1.0 0.0 0.0 0.0" material="" type="mesh" mesh="link_4.STL" class="visual" />
              <geom name="link_4_visual_1" pos="0 0 0" quat="1.0 0.0 0.0 0.0" material="" type="mesh" mesh="link_4_motor.STL" class="visual" />
              <body name="link_5" pos="-0.045 0.013097 0" quat="1.0 0.0 0.0 0.0">
                <joint name="joint_5" type="hinge" ref="0.0" class="motor" range="-3.14 3.14" axis="1 0 0" />
                <inertial pos="-0.019091 0.0053379 0.00018011" quat="1.0 0.0 0.0 0.0" mass="0.029277" diaginertia="3.5905e-06 6.8334e-06 8.1125e-06" />
                <geom name="link_5_collision_0" pos="0 0 0" quat="1.0 0.0 0.0 0.0" type="mesh" mesh="link_5.STL" class="collision" />
                <geom name="link_5_collision_1" pos="0 0 0" quat="1.0 0.0 0.0 0.0" type="mesh" mesh="link_5_motor.STL" class="collision" />
                <geom name="link_5_visual_0" pos="0 0 0" quat="1.0 0.0 0.0 0.0" material="" type="mesh" mesh="link_5.STL" class="visual" />
                <geom name="link_5_visual_1" pos="0 0 0" quat="1.0 0.0 0.0 0.0" material="" type="mesh" mesh="link_5_motor.STL" class="visual" />
                <body name="link_6" pos="-0.01315 -0.0075 0.0145" quat="1.0 0.0 0.0 0.0">
                  <joint name="joint_6" type="hinge" ref="0.0" class="motor" range="-2.45 0.032" axis="0 0 -1" />
                  <inertial pos="-0.02507 0.0010817 -0.01414" quat="1.0 0.0 0.0 0.0" mass="0.012831" diaginertia="1.5159e-06 3.449e-06 2.4565e-06" />
                  <geom name="link_6_collision" pos="0 0 0" quat="1.0 0.0 0.0 0.0" type="mesh" mesh="link_6.STL" class="collision" />
                  <geom name="link_6_visual" pos="0 0 0" quat="1.0 0.0 0.0 0.0" material="" type="mesh" mesh="link_6.STL" class="visual" />
                </body>
              </body>
            </body>
          </body>
        </body>
      </body>
      <site name="base_link_site" pos="0 0 0" quat="1 0 0 0" />
      <camera name="front_camera" mode="track" fovy="90.0" quat="4.329637285359678e-17 4.329637285359677e-17 0.7071067811865475 0.7071067811865476" pos="0.0 2.0 0.5" />
      <camera name="side_camera" mode="track" fovy="90.0" quat="-0.5 -0.4999999999999999 0.5 0.5000000000000001" pos="-2.0 0.0 0.5" />
    </body>
  </worldbody>

  <actuator>
    <motor name="joint_1_ctrl" joint="joint_1" class="motor" />
    <motor name="joint_2_ctrl" joint="joint_2" class="motor" />
    <motor name="joint_3_ctrl" joint="joint_3" class="motor" />
    <motor name="joint_4_ctrl" joint="joint_4" class="motor" />
    <motor name="joint_5_ctrl" joint="joint_5" class="motor" />
    <motor name="joint_6_ctrl" joint="joint_6" class="motor" />
  </actuator>

  <contact>
    <exclude body1="base_link" body2="link_1" />
    <exclude body1="link_1" body2="link_2" />
    <exclude body1="link_2" body2="link_3" />
    <exclude body1="link_3" body2="link_4" />
    <exclude body1="link_4" body2="link_5" />
    <exclude body1="link_5" body2="link_6" />
  </contact>

  <sensor>
    <framepos name="base_link_site_pos" objtype="site" objname="base_link_site" />
    <framequat name="base_link_site_quat" objtype="site" objname="base_link_site" />
    <framelinvel name="base_link_site_linvel" objtype="site" objname="base_link_site" />
    <frameangvel name="base_link_site_angvel" objtype="site" objname="base_link_site" />
    <velocimeter name="base_link_site_vel" site="base_link_site" />
  </sensor>
</mujoco>